REPLICA for shard_0 listening on 127.0.0.1:5004
Replica for shard_0 initialized at 127.0.0.1:5004
  -> Leader: 127.0.0.1:5001
Starting replica heartbeat loop...
Traceback (most recent call last):
  File "/Users/alaynanguyen/Documents/GitHub/262-final-project/server/shard.py", line 285, in <module>
    serve(args.role, args.shard_id, args.port, args.config)
  File "/Users/alaynanguyen/Documents/GitHub/262-final-project/server/shard.py", line 273, in serve
    servicer.on_server_start()
  File "/Users/alaynanguyen/Documents/GitHub/262-final-project/server/shard.py", line 58, in on_server_start
    response = stub.RegisterReplica(request)
               ^^^^^^^^^^^^^^^^^^^^^^^^^^^^^
  File "/opt/anaconda3/lib/python3.12/site-packages/grpc/_channel.py", line 1181, in __call__
    return _end_unary_response_blocking(state, call, False, None)
           ^^^^^^^^^^^^^^^^^^^^^^^^^^^^^^^^^^^^^^^^^^^^^^^^^^^^^^
  File "/opt/anaconda3/lib/python3.12/site-packages/grpc/_channel.py", line 1006, in _end_unary_response_blocking
    raise _InactiveRpcError(state)  # pytype: disable=not-instantiable
    ^^^^^^^^^^^^^^^^^^^^^^^^^^^^^^
grpc._channel._InactiveRpcError: <_InactiveRpcError of RPC that terminated with:
	status = StatusCode.UNKNOWN
	details = "Exception calling application: <_InactiveRpcError of RPC that terminated with:
	status = StatusCode.UNAVAILABLE
	details = "failed to connect to all addresses; last error: UNKNOWN: ipv4:127.0.0.1:5006: Failed to connect to remote host: connect: Connection refused (61)"
	debug_error_string = "UNKNOWN:Error received from peer  {created_time:"2025-04-24T23:25:48.479544-04:00", grpc_status:14, grpc_message:"failed to connect to all addresses; last error: UNKNOWN: ipv4:127.0.0.1:5006: Failed to connect to remote host: connect: Connection refused (61)"}"
>"
	debug_error_string = "UNKNOWN:Error received from peer  {grpc_message:"Exception calling application: <_InactiveRpcError of RPC that terminated with:\n\tstatus = StatusCode.UNAVAILABLE\n\tdetails = \"failed to connect to all addresses; last error: UNKNOWN: ipv4:127.0.0.1:5006: Failed to connect to remote host: connect: Connection refused (61)\"\n\tdebug_error_string = \"UNKNOWN:Error received from peer  {created_time:\"2025-04-24T23:25:48.479544-04:00\", grpc_status:14, grpc_message:\"failed to connect to all addresses; last error: UNKNOWN: ipv4:127.0.0.1:5006: Failed to connect to remote host: connect: Connection refused (61)\"}\"\n>", grpc_status:2, created_time:"2025-04-24T23:25:48.494887-04:00"}"
>
